/home/ahmad/.virtualenvs/ask/local/lib/python2.7/site-packages/Django-1.4.5-py2.7.egg/django/core/handlers/base.py TIME: 2013-08-01 22:49:34,757 MSG: base.py:handle_uncaught_exception:215 Internal Server Error: /
Traceback (most recent call last):
  File "/home/ahmad/.virtualenvs/ask/local/lib/python2.7/site-packages/Django-1.4.5-py2.7.egg/django/core/handlers/base.py", line 89, in get_response
    response = middleware_method(request)
  File "/home/ahmad/ask/askbot-devel/askbot/middleware/anon_user.py", line 50, in process_request
    if request.user.is_anonymous():
  File "/home/ahmad/.virtualenvs/ask/local/lib/python2.7/site-packages/Django-1.4.5-py2.7.egg/django/utils/functional.py", line 184, in inner
    self._setup()
  File "/home/ahmad/.virtualenvs/ask/local/lib/python2.7/site-packages/Django-1.4.5-py2.7.egg/django/utils/functional.py", line 248, in _setup
    self._wrapped = self._setupfunc()
  File "/home/ahmad/.virtualenvs/ask/local/lib/python2.7/site-packages/Django-1.4.5-py2.7.egg/django/contrib/auth/middleware.py", line 16, in <lambda>
    request.user = SimpleLazyObject(lambda: get_user(request))
  File "/home/ahmad/.virtualenvs/ask/local/lib/python2.7/site-packages/Django-1.4.5-py2.7.egg/django/contrib/auth/middleware.py", line 8, in get_user
    request._cached_user = auth.get_user(request)
  File "/home/ahmad/.virtualenvs/ask/local/lib/python2.7/site-packages/Django-1.4.5-py2.7.egg/django/contrib/auth/__init__.py", line 98, in get_user
    user_id = request.session[SESSION_KEY]
  File "/home/ahmad/.virtualenvs/ask/local/lib/python2.7/site-packages/Django-1.4.5-py2.7.egg/django/contrib/sessions/backends/base.py", line 39, in __getitem__
    return self._session[key]
  File "/home/ahmad/.virtualenvs/ask/local/lib/python2.7/site-packages/Django-1.4.5-py2.7.egg/django/contrib/sessions/backends/base.py", line 165, in _get_session
    self._session_cache = self.load()
  File "/home/ahmad/.virtualenvs/ask/local/lib/python2.7/site-packages/Django-1.4.5-py2.7.egg/django/contrib/sessions/backends/db.py", line 19, in load
    expire_date__gt=timezone.now()
  File "/home/ahmad/.virtualenvs/ask/local/lib/python2.7/site-packages/Django-1.4.5-py2.7.egg/django/db/models/manager.py", line 131, in get
    return self.get_query_set().get(*args, **kwargs)
  File "/home/ahmad/.virtualenvs/ask/local/lib/python2.7/site-packages/Django-1.4.5-py2.7.egg/django/db/models/query.py", line 361, in get
    num = len(clone)
  File "/home/ahmad/.virtualenvs/ask/local/lib/python2.7/site-packages/Django-1.4.5-py2.7.egg/django/db/models/query.py", line 85, in __len__
    self._result_cache = list(self.iterator())
  File "/home/ahmad/.virtualenvs/ask/local/lib/python2.7/site-packages/Django-1.4.5-py2.7.egg/django/db/models/query.py", line 291, in iterator
    for row in compiler.results_iter():
  File "/home/ahmad/.virtualenvs/ask/local/lib/python2.7/site-packages/Django-1.4.5-py2.7.egg/django/db/models/sql/compiler.py", line 763, in results_iter
    for rows in self.execute_sql(MULTI):
  File "/home/ahmad/.virtualenvs/ask/local/lib/python2.7/site-packages/Django-1.4.5-py2.7.egg/django/db/models/sql/compiler.py", line 818, in execute_sql
    cursor.execute(sql, params)
  File "/home/ahmad/.virtualenvs/ask/local/lib/python2.7/site-packages/Django-1.4.5-py2.7.egg/django/db/backends/util.py", line 40, in execute
    return self.cursor.execute(sql, params)
  File "/home/ahmad/.virtualenvs/ask/local/lib/python2.7/site-packages/Django-1.4.5-py2.7.egg/django/db/backends/postgresql_psycopg2/base.py", line 52, in execute
    return self.cursor.execute(query, args)
DatabaseError: relation "django_session" does not exist
LINE 1: ...ession_data", "django_session"."expire_date" FROM "django_se...
                                                             ^

/home/ahmad/.virtualenvs/ask/local/lib/python2.7/site-packages/Django-1.4.5-py2.7.egg/django/core/handlers/base.py TIME: 2013-08-01 22:49:34,973 MSG: base.py:handle_uncaught_exception:215 Internal Server Error: /
Traceback (most recent call last):
  File "/home/ahmad/.virtualenvs/ask/local/lib/python2.7/site-packages/Django-1.4.5-py2.7.egg/django/core/handlers/base.py", line 188, in get_response
    response = middleware_method(request, response)
  File "/home/ahmad/ask/askbot-devel/askbot/middleware/anon_user.py", line 76, in process_response
    request.user.is_authenticated() and \
  File "/home/ahmad/.virtualenvs/ask/local/lib/python2.7/site-packages/Django-1.4.5-py2.7.egg/django/utils/functional.py", line 184, in inner
    self._setup()
  File "/home/ahmad/.virtualenvs/ask/local/lib/python2.7/site-packages/Django-1.4.5-py2.7.egg/django/utils/functional.py", line 248, in _setup
    self._wrapped = self._setupfunc()
  File "/home/ahmad/.virtualenvs/ask/local/lib/python2.7/site-packages/Django-1.4.5-py2.7.egg/django/contrib/auth/middleware.py", line 16, in <lambda>
    request.user = SimpleLazyObject(lambda: get_user(request))
  File "/home/ahmad/.virtualenvs/ask/local/lib/python2.7/site-packages/Django-1.4.5-py2.7.egg/django/contrib/auth/middleware.py", line 8, in get_user
    request._cached_user = auth.get_user(request)
  File "/home/ahmad/.virtualenvs/ask/local/lib/python2.7/site-packages/Django-1.4.5-py2.7.egg/django/contrib/auth/__init__.py", line 98, in get_user
    user_id = request.session[SESSION_KEY]
  File "/home/ahmad/.virtualenvs/ask/local/lib/python2.7/site-packages/Django-1.4.5-py2.7.egg/django/contrib/sessions/backends/base.py", line 39, in __getitem__
    return self._session[key]
  File "/home/ahmad/.virtualenvs/ask/local/lib/python2.7/site-packages/Django-1.4.5-py2.7.egg/django/contrib/sessions/backends/base.py", line 165, in _get_session
    self._session_cache = self.load()
  File "/home/ahmad/.virtualenvs/ask/local/lib/python2.7/site-packages/Django-1.4.5-py2.7.egg/django/contrib/sessions/backends/db.py", line 19, in load
    expire_date__gt=timezone.now()
  File "/home/ahmad/.virtualenvs/ask/local/lib/python2.7/site-packages/Django-1.4.5-py2.7.egg/django/db/models/manager.py", line 131, in get
    return self.get_query_set().get(*args, **kwargs)
  File "/home/ahmad/.virtualenvs/ask/local/lib/python2.7/site-packages/Django-1.4.5-py2.7.egg/django/db/models/query.py", line 361, in get
    num = len(clone)
  File "/home/ahmad/.virtualenvs/ask/local/lib/python2.7/site-packages/Django-1.4.5-py2.7.egg/django/db/models/query.py", line 85, in __len__
    self._result_cache = list(self.iterator())
  File "/home/ahmad/.virtualenvs/ask/local/lib/python2.7/site-packages/Django-1.4.5-py2.7.egg/django/db/models/query.py", line 291, in iterator
    for row in compiler.results_iter():
  File "/home/ahmad/.virtualenvs/ask/local/lib/python2.7/site-packages/Django-1.4.5-py2.7.egg/django/db/models/sql/compiler.py", line 763, in results_iter
    for rows in self.execute_sql(MULTI):
  File "/home/ahmad/.virtualenvs/ask/local/lib/python2.7/site-packages/Django-1.4.5-py2.7.egg/django/db/models/sql/compiler.py", line 818, in execute_sql
    cursor.execute(sql, params)
  File "/home/ahmad/.virtualenvs/ask/local/lib/python2.7/site-packages/Django-1.4.5-py2.7.egg/django/db/backends/util.py", line 40, in execute
    return self.cursor.execute(sql, params)
  File "/home/ahmad/.virtualenvs/ask/local/lib/python2.7/site-packages/Django-1.4.5-py2.7.egg/django/db/backends/postgresql_psycopg2/base.py", line 52, in execute
    return self.cursor.execute(query, args)
DatabaseError: current transaction is aborted, commands ignored until end of transaction block

